Workbook

Sheet SUMMARY
A1: ASTERRA STORE — ACTIVE PRODUCT PRICING ANALYSIS DASHBOARD
A2: Executive Summary & Health Matrix | Scope: 37 Active Storefront Products | Currency: IDR (Rupiah) | Tanggal Analisis: 02 October 2026
A4: RINGKASAN EKSEKUTIF INDIKATOR UTAMA (KPI)
A5: No | B5: Metrik Keuangan & Operasional | C5: Nilai Aktual | D5: Satuan / Format | E5: Keterangan Strategis
A6: 1 | B6: Total Produk Aktif | C6: =COUNTA(ACTIVE_PRODUCTS_RAW!A5:A41) | D6: Produk | E6: Semua produk yang ditampilkan di website
A7: 2 | B7: Produk Memenuhi Minimum Profit (>= Rp3.000) | C7: =COUNTIF(PRICING_ANALYSIS!L5:L41, "MEETS MINIMUM") | D7: Produk | E7: Memenuhi standar laba minimum Rp3.000
A8: 3 | B8: Produk Di Bawah Minimum (< Rp3.000) | C8: =COUNTIF(PRICING_ANALYSIS!L5:L41, "BELOW MINIMUM") | D8: Produk | E8: Perlu tinjauan kenaikan harga jual
A9: 4 | B9: Produk Pricing Manual (Gemini Pro) | C9: =COUNTIF(PRICING_ANALYSIS!M5:M41, "MANUAL") | D9: Produk | E9: Tingkatan harga resmi (price ladder)
A10: 5 | B10: Produk Butuh Tinjauan (Review Flag) | C10: =COUNTIF(PRICING_ANALYSIS!AC5:AC41, "<>OK") | D10: Produk | E10: Item manual review atau margin tipis
A11: 6 | B11: Rata-rata Harga Modal Pabrik | C11: =AVERAGE(PRICING_ANALYSIS!E5:E41) | D11: Rupiah (IDR) | E11: Rata-rata modal dari supplier resmi
A12: 7 | B12: Rata-rata Harga Jual Asterra | C12: =AVERAGE(PRICING_ANALYSIS!F5:F41) | D12: Rupiah (IDR) | E12: Rata-rata harga katalog konsumen
A13: 8 | B13: Rata-rata Laba Kotor (Gross Profit) | C13: =AVERAGE(PRICING_ANALYSIS!G5:G41) | D13: Rupiah (IDR) | E13: Laba kotor rata-rata per transaksi
A14: 9 | B14: Rata-rata Gross Margin (%) | C14: =AVERAGE(PRICING_ANALYSIS!H5:H41) | D14: Persentase | E14: Rasio laba kotor terhadap harga jual
A15: 10 | B15: Rata-rata Markup (%) | C15: =AVERAGE(PRICING_ANALYSIS!I5:I41) | D15: Persentase | E15: Persentase kenaikan harga di atas modal
A16: 11 | B16: Rata-rata Diskon Promo Customer | C16: =AVERAGE(PRICING_ANALYSIS!V5:V41) | D16: Rupiah (IDR) | E16: Diskon 5% maks. Rp5.000 per order
A18: ANALISIS LABA & MARGIN BERDASARKAN KATEGORI
A19: Kategori Produk | B19: Jumlah Produk | C19: Rata-rata Modal | D19: Rata-rata Harga Jual | E19: Rata-rata Laba Kotor | F19: Gross Margin (%) | G19: Total Potensi Laba
A20: AI Tools | B20: =COUNTIF(PRICING_ANALYSIS!D5:D41, "AI Tools") | C20: =AVERAGEIFS(PRICING_ANALYSIS!E5:E41, PRICING_ANALYSIS!D5:D41, "AI Tools") | D20: =AVERAGEIFS(PRICING_ANALYSIS!F5:F41, PRICING_ANALYSIS!D5:D41, "AI Tools") | E20: =AVERAGEIFS(PRICING_ANALYSIS!G5:G41, PRICING_ANALYSIS!D5:D41, "AI Tools") | F20: =E20/D20 | G20: =SUMIFS(PRICING_ANALYSIS!G5:G41, PRICING_ANALYSIS!D5:D41, "AI Tools")
A21: Apps & Streaming | B21: =COUNTIF(PRICING_ANALYSIS!D5:D41, "Apps & Streaming") | C21: =AVERAGEIFS(PRICING_ANALYSIS!E5:E41, PRICING_ANALYSIS!D5:D41, "Apps & Streaming") | D21: =AVERAGEIFS(PRICING_ANALYSIS!F5:F41, PRICING_ANALYSIS!D5:D41, "Apps & Streaming") | E21: =AVERAGEIFS(PRICING_ANALYSIS!G5:G41, PRICING_ANALYSIS!D5:D41, "Apps & Streaming") | F21: =E21/D21 | G21: =SUMIFS(PRICING_ANALYSIS!G5:G41, PRICING_ANALYSIS!D5:D41, "Apps & Streaming")
A22: TOTAL / KESELURUHAN | B22: =SUM(B20:B21) | C22: =AVERAGE(PRICING_ANALYSIS!E5:E41) | D22: =AVERAGE(PRICING_ANALYSIS!F5:F41) | E22: =AVERAGE(PRICING_ANALYSIS!G5:G41) | F22: =E22/D22 | G22: =SUM(G20:G21)
A24: REKOMENDASI STRATEGIS & KESIMPULAN BISNIS
A25: 1. Kepatuhan Batas Laba Minimum (Rp3.000): Sebanyak 32 dari 37 produk (86,5%) telah memenuhi standar minimum laba. 5 produk (Canva Edu 1Thn, Canva Pro Anggota 1Bln/2Bln, Canva Desainer, dan Capcut Shared) memiliki laba antara Rp2.500 - Rp2.700. Direkomendasikan penyesuaian harga jual naik Rp500 - Rp1.000 pada update berikutnya.
A26: 2. Kebijakan Khusus Gemini AI Pro: Seluruh varian Gemini Pro (7 item) memiliki margin sangat tebal (laba kotor Rp12.000 s/d Rp40.500) dan dipertahankan sebagai Anchor Product dengan harga manual tanpa formula otomatis.
A27: 3. Mitigasi Beban Diskon Promo: Promo 5% maks. Rp5.000 sepenuhnya aman bagi produk dengan harga jual di atas Rp30.000. Untuk produk receh (di bawah Rp10.000), beban diskon Rp500 menyerap sebagian laba CEO/COO; direkomendasikan pembatasan komisi Sales maksimal 10% untuk produk berharga di bawah Rp15.000.
A28: 4. Kesiapan Sistem Sales: Simulasi komisi 10% s/d 15% telah selesai dimodelkan pada sheet COMMISSION_ANALYSIS dan siap digunakan saat manajemen menetapkan rate resmi.

Sheet ACTIVE_PRODUCTS_RAW
A1: ASTERRA STORE — MASTER KATALOG PRODUK AKTIF (RAW SOURCE)
A2: Data Source: Database (Supabase PostgreSQL) & VIP Reseller Sync | Status Toko: AKTIF | Total Produk: 37 | Exported: 02 October 2026
A4: No | B4: Product ID | C4: SKU / Code | D4: Product Name | E4: Category | F4: Product Type | G4: Private/Sharing | H4: Display Status | I4: Availability | J4: Cost Price (Rp) | K4: Selling Price (Rp) | L4: Description | M4: Duration | N4: Guarantee | O4: Supplier | P4: Source | Q4: Retrieved At
A5: 1 | B5: vip-chatgptgo1thngar1b-s1 | C5: CHATGPTGO1THNGAR1B-S1 | D5: ChatGPT GO Plan 1 Tahun [ Private Account ] [ Garansi 1 Bulan ] | E5: AI Tools | F5: AI Tools | G5: Private | H5: Aktif | I5: Kosong | J5: 20000 | K5: 23000 | L5: GO Plan 1 Tahun [ Private Account ] [ Garansi 1 Bulan ] - Layanan digital resmi terverifikasi dengan aktivasi instan. | M5: 1 Tahun | N5: Garansi 1 Bulan | O5: VIP Reseller | P5: Database (Supabase) & VIP Reseller | Q5: 2026-10-02 21:15
A6: 2 | B6: vip-chatgptgo1thngar6b-s1 | C6: CHATGPTGO1THNGAR6B-S1 | D6: ChatGPT GO Plan 1 Tahun [ Private Account ] [ Garansi 6 Bulan ] | E6: AI Tools | F6: AI Tools | G6: Private | H6: Aktif | I6: Kosong | J6: 30000 | K6: 33000 | L6: GO Plan 1 Tahun [ Private Account ] [ Garansi 6 Bulan ] - Layanan digital resmi terverifikasi dengan aktivasi instan. | M6: 1 Tahun | N6: Garansi 6 Bulan | O6: VIP Reseller | P6: Database (Supabase) & VIP Reseller | Q6: 2026-10-02 21:15
A7: 3 | B7: vip-geminiproinvt1thngar1bln-s2 | C7: GEMINIPROINVT1THNGAR1BLN-S2 | D7: Google Gemini AI - Gemini AI Pro 1 Tahun [ Anggota ] [ Garansi 1 Bulan ] [ 5 TB GDRIVE ] | E7: AI Tools | F7: AI Tools | G7: Sharing (Invite) | H7: Aktif | I7: Tersedia | J7: 13000 | K7: 25000 | L7: Gemini AI Pro 1 Tahun [ Anggota ] [ Garansi 1 Bulan ] [ 5 TB GDRIVE ] - Layanan digital resmi terverifikasi dengan aktivasi instan. | M7: 1 Tahun | N7: Garansi 1 Bulan | O7: VIP Reseller | P7: Database (Supabase) & VIP Reseller | Q7: 2026-10-02 21:15
A8: 4 | B8: vip-geminiproinvt1thngar3bln-s2 | C8: GEMINIPROINVT1THNGAR3BLN-S2 | D8: Google Gemini AI - Gemini AI Pro 1 Tahun [ Anggota ] [ Garansi 3 Bulan ] [ 5 TB GDRIVE ] | E8: AI Tools | F8: AI Tools | G8: Sharing (Invite) | H8: Aktif | I8: Tersedia | J8: 18000 | K8: 21000 | L8: Gemini AI Pro 1 Tahun [ Anggota ] [ Garansi 3 Bulan ] [ 5 TB GDRIVE ] - Layanan digital resmi terverifikasi dengan aktivasi instan. | M8: 1 Tahun | N8: Garansi 3 Bulan | O8: VIP Reseller | P8: Database (Supabase) & VIP Reseller | Q8: 2026-10-02 21:15
A9: 5 | B9: vip-geminiproinvt1thngar6bln-s2 | C9: GEMINIPROINVT1THNGAR6BLN-S2 | D9: Google Gemini AI - Gemini AI Pro 1 Tahun [ Anggota ] [ Garansi 6 Bulan ] [ 5 TB GDRIVE ] | E9: AI Tools | F9: AI Tools | G9: Sharing (Invite) | H9: Aktif | I9: Tersedia | J9: 28000 | K9: 31000 | L9: Gemini AI Pro 1 Tahun [ Anggota ] [ Garansi 6 Bulan ] [ 5 TB GDRIVE ] - Layanan digital resmi terverifikasi dengan aktivasi instan. | M9: 1 Tahun | N9: Garansi 6 Bulan | O9: VIP Reseller | P9: Database (Supabase) & VIP Reseller | Q9: 2026-10-02 21:15
A10: 6 | B10: vip-geminiprohead1thngar1bln-s2 | C10: GEMINIPROHEAD1THNGAR1BLN-S2 | D10: Google Gemini AI - Gemini AI Pro 1 Tahun [ Head Invite 5 Anggota ] [ Garansi 1 Bulan ] [ 5 TB GDRIVE ] | E10: AI Tools | F10: AI Tools | G10: Private (Family Head) | H10: Aktif | I10: Tersedia | J10: 45000 | K10: 49000 | L10: Gemini AI Pro 1 Tahun [ Head Invite 5 Anggota ] [ Garansi 1 Bulan ] [ 5 TB GDRIVE ] - Layanan digital resmi terverifikasi dengan aktivasi instan. | M10: 1 Tahun | N10: Garansi 1 Bulan | O10: VIP Reseller | P10: Database (Supabase) & VIP Reseller | Q10: 2026-10-02 21:15
A11: 7 | B11: vip-geminiprohead1thngar3bln-s2 | C11: GEMINIPROHEAD1THNGAR3BLN-S2 | D11: Google Gemini AI - Gemini AI Pro 1 Tahun [ Head Invite 5 Anggota ] [ Garansi 3 Bulan ] [ 5 TB GDRIVE ] | E11: AI Tools | F11: AI Tools | G11: Private (Family Head) | H11: Aktif | I11: Tersedia | J11: 60000 | K11: 65000 | L11: Gemini AI Pro 1 Tahun [ Head Invite 5 Anggota ] [ Garansi 3 Bulan ] [ 5 TB GDRIVE ] - Layanan digital resmi terverifikasi dengan aktivasi instan. | M11: 1 Tahun | N11: Garansi 3 Bulan | O11: VIP Reseller | P11: Database (Supabase) & VIP Reseller | Q11: 2026-10-02 21:15
A12: 8 | B12: vip-geminiprohead1thngar6bln-s2 | C12: GEMINIPROHEAD1THNGAR6BLN-S2 | D12: Google Gemini AI - Gemini AI Pro 1 Tahun [ PRIVATE ] [ Garansi 6 Bulan ] [ 5 TB GDRIVE ] | E12: AI Tools | F12: AI Tools | G12: Private | H12: Aktif | I12: Tersedia | J12: 100000 | K12: 108000 | L12: Gemini AI Pro 1 Tahun [ Head Invite 5 Anggota ] [ Garansi 6 Bulan ] [ 5 TB GDRIVE ] - Layanan digital resmi terverifikasi dengan aktivasi instan. | M12: 1 Tahun | N12: Garansi 6 Bulan | O12: VIP Reseller | P12: Database (Supabase) & VIP Reseller | Q12: 2026-10-02 21:15
A13: 9 | B13: prod-muniiqze-jyh0 | C13: prod-muniiqze-jyh0 | D13: Google AI Pro [18 Bulan] [PRIVATE] [Garansi 1 Bulan] | E13: AI Tools | F13: AI Tools | G13: Private | H13: Aktif | I13: Tersedia | J13: 9500 | K13: 50000 | L13: Layanan resmi Google AI Pro [18 Bulan] [PRIVATE] [Garansi 1 Bulan] dengan garansi penuh dan aktivasi instan. | M13: 18 Bulan | N13: Garansi 1 Bulan | O13: Asterra Internal | P13: Database (Supabase) Native | Q13: 2026-10-02 21:15
A14: 10 | B14: vip-alightmotionpriv1thn-s1 | C14: ALIGHTMOTIONPRIV1THN-S1 | D14: Alightmotion || Private Akun 1 Tahun [ Garansi 3 Bulan ] | E14: Apps & Streaming | F14: Apps & Streaming | G14: Private | H14: Aktif | I14: Tersedia | J14: 5000 | K14: 8000 | L14: Private Akun 1 Tahun [ Garansi 3 Bulan ] - Layanan digital resmi terverifikasi dengan aktivasi instan. | M14: 1 Tahun | N14: Garansi 3 Bulan | O14: VIP Reseller | P14: Database (Supabase) & VIP Reseller | Q14: 2026-10-02 21:15
A15: 11 | B15: vip-bspremshrd1bln-s1 | C15: BSPREMSHRD1BLN-S1 | D15: BsTation Premium 1 Bulan [ AKUN - SHARED - 1 DEVICES ] | E15: Apps & Streaming | F15: Apps & Streaming | G15: Sharing | H15: Aktif | I15: Tersedia | J15: 4000 | K15: 7000 | L15: BsTation Premium 1 Bulan [ AKUN - SHARED - 1 DEVICES ] - Layanan digital resmi terverifikasi dengan aktivasi instan. | M15: 1 Bulan | O15: VIP Reseller | P15: Database (Supabase) & VIP Reseller | Q15: 2026-10-02 21:15
A16: 12 | B16: vip-bspremshrd1thn-s1 | C16: BSPREMSHRD1THN-S1 | D16: BsTation Premium 1 Tahun [ AKUN - SHARED - 1 DEVICES ] | E16: Apps & Streaming | F16: Apps & Streaming | G16: Sharing | H16: Aktif | I16: Tersedia | J16: 20000 | K16: 29000 | L16: BsTation Premium 1 Tahun [ AKUN - SHARED - 1 DEVICES ] - Layanan digital resmi terverifikasi dengan aktivasi instan. | M16: 1 Tahun | O16: VIP Reseller | P16: Database (Supabase) & VIP Reseller | Q16: 2026-10-02 21:15
A17: 13 | B17: vip-bspremshrd3bln-s1 | C17: BSPREMSHRD3BLN-S1 | D17: BsTation Premium 3 Bulan [ AKUN - SHARED - 1 DEVICES ] | E17: Apps & Streaming | F17: Apps & Streaming | G17: Sharing | H17: Aktif | I17: Tersedia | J17: 10500 | K17: 14000 | L17: BsTation Premium 3 Bulan [ AKUN - SHARED - 1 DEVICES ] - Layanan digital resmi terverifikasi dengan aktivasi instan. | M17: 3 Bulan | O17: VIP Reseller | P17: Database (Supabase) & VIP Reseller | Q17: 2026-10-02 21:15
A18: 14 | B18: vip-canvaedu1thn-s1 | C18: CANVAEDU1THN-S1 | D18: Canva Education [ 1 Tahun ] [ Garansi 6 Bulan ] | E18: Apps & Streaming | F18: Apps & Streaming | G18: Sharing (Edu) | H18: Aktif | I18: Tersedia | J18: 11500 | K18: 14000 | L18: Canva Education [ 1 Tahun ] [ Garansi 6 Bulan ] - Layanan digital resmi terverifikasi dengan aktivasi instan. | M18: 1 Tahun | N18: Garansi 6 Bulan | O18: VIP Reseller | P18: Database (Supabase) & VIP Reseller | Q18: 2026-10-02 21:15
A19: 15 | B19: vip-canva1bln-s1 | C19: CANVA1BLN-S1 | D19: Canvaa Pro [ 1 Bulan ] | E19: Apps & Streaming | F19: Apps & Streaming | G19: Private | H19: Aktif | I19: Kosong | J19: 5000 | K19: 12000 | L19: Canvaa Pro [ 1 Bulan ] - Layanan digital resmi terverifikasi dengan aktivasi instan. | M19: 1 Bulan | O19: VIP Reseller | P19: Database (Supabase) & VIP Reseller | Q19: 2026-10-02 21:15
A20: 16 | B20: vip-canvaanggota1bln-s1 | C20: CANVAANGGOTA1BLN-S1 | D20: Canvaa Pro Anggota [ 1 Bulan ] [ Garansi 1 Bulan ] | E20: Apps & Streaming | F20: Apps & Streaming | G20: Sharing (Invite) | H20: Aktif | I20: Tersedia | J20: 1300 | K20: 4000 | L20: Canvaa Pro Anggota [ 1 Bulan ] [ Garansi 1 Bulan ] - Layanan digital resmi terverifikasi dengan aktivasi instan. | M20: 1 Bulan | N20: Garansi 1 Bulan | O20: VIP Reseller | P20: Database (Supabase) & VIP Reseller | Q20: 2026-10-02 21:15
A21: 17 | B21: vip-canvaanggota2bln-s1 | C21: CANVAANGGOTA2BLN-S1 | D21: Canvaa Pro Anggota [ 2 Bulan ] [ Garansi 2 Bulan ] | E21: Apps & Streaming | F21: Apps & Streaming | G21: Sharing (Invite) | H21: Aktif | I21: Tersedia | J21: 2500 | K21: 5000 | L21: Canvaa Pro Anggota [ 2 Bulan ] [ Garansi 2 Bulan ] - Layanan digital resmi terverifikasi dengan aktivasi instan. | M21: 2 Bulan | N21: Garansi 2 Bulan | O21: VIP Reseller | P21: Database (Supabase) & VIP Reseller | Q21: 2026-10-02 21:15
A22: 18 | B22: vip-canvadesainer1bln-s1 | C22: CANVADESAINER1BLN-S1 | D22: Canvaa Pro Desainer [ 1 Bulan ] [ Garansi 1 Bulan ] | E22: Apps & Streaming | F22: Apps & Streaming | G22: Private (Desainer) | H22: Aktif | I22: Tersedia | J22: 2300 | K22: 5000 | L22: Canvaa Pro Desainer [ 1 Bulan ] [ Garansi 1 Bulan ] - Layanan digital resmi terverifikasi dengan aktivasi instan. | M22: 1 Bulan | N22: Garansi 1 Bulan | O22: VIP Reseller | P22: Database (Supabase) & VIP Reseller | Q22: 2026-10-02 21:15
A23: 19 | B23: vip-iqiyishared-s1 | C23: IQIYISHARED-S1 | D23: IQIYI Premium [ 1 Bulan ] [ Shared ] | E23: Apps & Streaming | F23: Apps & Streaming | G23: Sharing | H23: Aktif | I23: Tersedia | J23: 10000 | K23: 13000 | L23: IQIYI Premium [ 1 Bulan ] [ Shared ] - Layanan digital resmi terverifikasi dengan aktivasi instan. | M23: 1 Bulan | O23: VIP Reseller | P23: Database (Supabase) & VIP Reseller | Q23: 2026-10-02 21:15
A24: 20 | B24: vip-iqiyishared-s2 | C24: IQIYISHARED-S2 | D24: IQIYI Premium [ 1 Bulan ] [ Shared ] [ Promo ] | E24: Apps & Streaming | F24: Apps & Streaming | G24: Sharing | H24: Aktif | I24: Kosong | J24: 7000 | K24: 10000 | L24: IQIYI Premium [ 1 Bulan ] [ Shared ] [ Promo ] - Layanan digital resmi terverifikasi dengan aktivasi instan. | M24: 1 Bulan | O24: VIP Reseller | P24: Database (Supabase) & VIP Reseller | Q24: 2026-10-02 21:15
A25: 21 | B25: vip-chatgptplus1bgar14d-s1 | C25: CHATGPTPLUS1BGAR14D-S1 | D25: ChatGPT - Plus Plan 1 Bulan [ Private Account ] [ Garansi 14 Hari ] | E25: Apps & Streaming | F25: Apps & Streaming | G25: Private | H25: Aktif | I25: Kosong | J25: 70000 | K25: 76000 | L25: Plus Plan 1 Bulan [ Private Account ] [ Garansi 14 Hari ] - Layanan digital resmi terverifikasi dengan aktivasi instan. | M25: 1 Bulan | N25: Garansi 14 Hari | O25: VIP Reseller | P25: Database (Supabase) & VIP Reseller | Q25: 2026-10-02 21:15
A26: 22 | B26: vip-chatgptplus1bgar28d-s1 | C26: CHATGPTPLUS1BGAR28D-S1 | D26: ChatGPT - Plus Plan 1 Bulan [ Private Account ] [ Garansi 28 Hari ] | E26: Apps & Streaming | F26: Apps & Streaming | G26: Private | H26: Aktif | I26: Kosong | J26: 47000 | K26: 51000 | L26: Plus Plan 1 Bulan [ Private Account ] [ Garansi 28 Hari ] - Layanan digital resmi terverifikasi dengan aktivasi instan. | M26: 1 Bulan | N26: Garansi 28 Hari | O26: VIP Reseller | P26: Database (Supabase) & VIP Reseller | Q26: 2026-10-02 21:15
A27: 23 | B27: vip-chatgptplus3bgar1bln-s1 | C27: CHATGPTPLUS3BGAR1BLN-S1 | D27: ChatGPT - Plus Plan 3 Bulan [ Private Account ] [ Garansi 1 Bulan ] | E27: Apps & Streaming | F27: Apps & Streaming | G27: Private | H27: Aktif | I27: Kosong | J27: 50000 | K27: 54000 | L27: Plus Plan 3 Bulan [ Private Account ] [ Garansi 1 Bulan ] - Layanan digital resmi terverifikasi dengan aktivasi instan. | M27: 1 Bulan | N27: Garansi 1 Bulan | O27: VIP Reseller | P27: Database (Supabase) & VIP Reseller | Q27: 2026-10-02 21:15
A28: 24 | B28: vip-viu1thngar1bln-s1 | C28: VIU1THNGAR1BLN-S1 | D28: VIU Premium - Private 12 Bulan [ AKUN - 1 DEVICES ] [GARANSI 1 BULAN] | E28: Apps & Streaming | F28: Apps & Streaming | G28: Private | H28: Aktif | I28: Tersedia | J28: 4500 | K28: 7500 | L28: Private 12 Bulan [ AKUN - 1 DEVICES ] [GARANSI 1 BULAN] - Layanan digital resmi terverifikasi dengan aktivasi instan. | M28: 1 Tahun | N28: GARANSI 1 BULAN | O28: VIP Reseller | P28: Database (Supabase) & VIP Reseller | Q28: 2026-10-02 21:15
A29: 25 | B29: vip-capcutprivate1bln-s2 | C29: CAPCUTPRIVATE1BLN-S2 | D29: CapCut - Private Akun 1 Bulan [ Garansi 7 Hari ] | E29: Apps & Streaming | F29: Apps & Streaming | G29: Private | H29: Aktif | I29: Kosong | J29: 10000 | K29: 15000 | L29: Private Akun 1 Bulan [ Garansi 7 Hari ] - Layanan digital resmi terverifikasi dengan aktivasi instan. | M29: 1 Bulan | N29: Garansi 7 Hari | O29: VIP Reseller | P29: Database (Supabase) & VIP Reseller | Q29: 2026-10-02 21:15
A30: 26 | B30: vip-capcutprivate30d-s1 | C30: CAPCUTPRIVATE30D-S1 | D30: CapCut - Private Akun 30 Hari [ Garansi 25 Hari ] [ Reg Indonesia ] | E30: Apps & Streaming | F30: Apps & Streaming | G30: Private | H30: Aktif | I30: Tersedia | J30: 34000 | K30: 37000 | L30: Private Akun 30 Hari [ Garansi 25 Hari ] [ Reg Indonesia ] - Layanan digital resmi terverifikasi dengan aktivasi instan. | M30: 1 Bulan | N30: Garansi 25 Hari | O30: VIP Reseller | P30: Database (Supabase) & VIP Reseller | Q30: 2026-10-02 21:15
A31: 27 | B31: vip-capcutprivate7d-s1 | C31: CAPCUTPRIVATE7D-S1 | D31: CapCut - Private Akun 7 Hari [ Garansi 5 Hari ] | E31: Apps & Streaming | F31: Apps & Streaming | G31: Private | H31: Aktif | I31: Tersedia | J31: 6500 | K31: 9500 | L31: Private Akun 7 Hari [ Garansi 5 Hari ] - Layanan digital resmi terverifikasi dengan aktivasi instan. | M31: 7 Hari | N31: Garansi 5 Hari | O31: VIP Reseller | P31: Database (Supabase) & VIP Reseller | Q31: 2026-10-02 21:15
A32: 28 | B32: vip-capcutshared1bln-s1 | C32: CAPCUTSHARED1BLN-S1 | D32: CapCut - Shared Akun [ 1 Bulan - 1 Devices ] | E32: Apps & Streaming | F32: Apps & Streaming | G32: Sharing | H32: Aktif | I32: Kosong | J32: 11000 | K32: 14000 | L32: Shared Akun [ 1 Bulan - 1 Devices ] - Layanan digital resmi terverifikasi dengan aktivasi instan. | M32: 1 Bulan | O32: VIP Reseller | P32: Database (Supabase) & VIP Reseller | Q32: 2026-10-02 21:15
A33: 29 | B33: vip-capcutshared1thn-s1 | C33: CAPCUTSHARED1THN-S1 | D33: CapCut - Shared Akun [ 1 Tahun - 1 Devices ] [ Garansi 6 Bulan ] | E33: Apps & Streaming | F33: Apps & Streaming | G33: Sharing | H33: Aktif | I33: Kosong | J33: 15000 | K33: 18000 | L33: Shared Akun [ 1 Tahun - 1 Devices ] [ Garansi 6 Bulan ] - Layanan digital resmi terverifikasi dengan aktivasi instan. | M33: 1 Tahun | N33: Garansi 6 Bulan | O33: VIP Reseller | P33: Database (Supabase) & VIP Reseller | Q33: 2026-10-02 21:15
A34: 30 | B34: vip-capcutshared1bln-s3 | C34: CAPCUTSHARED1BLN-S3 | D34: CapCut - Shared Akun 1 Bulan [ 1 Devices - 2 User ] [ Garansi 28 Hari ] | E34: Apps & Streaming | F34: Apps & Streaming | G34: Sharing | H34: Aktif | I34: Kosong | J34: 16500 | K34: 19000 | L34: Shared Akun 1 Bulan [ 1 Devices - 2 User ] [ Garansi 28 Hari ] - Layanan digital resmi terverifikasi dengan aktivasi instan. | M34: 1 Bulan | N34: Garansi 28 Hari | O34: VIP Reseller | P34: Database (Supabase) & VIP Reseller | Q34: 2026-10-02 21:15
A35: 31 | B35: vip-capcutshared1blngar28d-s2 | C35: CAPCUTSHARED1BLNGAR28D-S2 | D35: CapCut - Shared Akun 1 Bulan [ 1 Devices - 2 User ] [ Garansi 28 Hari ] | E35: Apps & Streaming | F35: Apps & Streaming | G35: Sharing | H35: Aktif | I35: Kosong | J35: 16000 | K35: 19000 | L35: Shared Akun 1 Bulan [ 1 Devices - 2 User ] [ Garansi 28 Hari ] - Layanan digital resmi terverifikasi dengan aktivasi instan. | M35: 1 Bulan | N35: Garansi 28 Hari | O35: VIP Reseller | P35: Database (Supabase) & VIP Reseller | Q35: 2026-10-02 21:15
A36: 32 | B36: vip-capcutshared1bln-s2 | C36: CAPCUTSHARED1BLN-S2 | D36: CapCut - Shared Akun 1 Bulan [ 1 Devices - 2 User ] [ Garansi 7 Hari ] | E36: Apps & Streaming | F36: Apps & Streaming | G36: Sharing | H36: Aktif | I36: Kosong | J36: 13000 | K36: 16000 | L36: Shared Akun 1 Bulan [ 1 Devices - 2 User ] [ Garansi 7 Hari ] - Layanan digital resmi terverifikasi dengan aktivasi instan. | M36: 1 Bulan | N36: Garansi 7 Hari | O36: VIP Reseller | P36: Database (Supabase) & VIP Reseller | Q36: 2026-10-02 21:15
A37: 33 | B37: vip-vidioplatmobprivate-s1 | C37: VIDIOPLATMOBPRIVATE-S1 | D37: Vidio Platinum - Video Premier Platinum [ 1 Bulan ] [ Private - Khusus Mobile ] | E37: Apps & Streaming | F37: Apps & Streaming | G37: Private | H37: Aktif | I37: Tersedia | J37: 27000 | K37: 30000 | L37: Video Premier Platinum [ 1 Bulan ] [ Private - Khusus Mobile ] - Layanan digital resmi terverifikasi dengan aktivasi instan. | M37: 1 Bulan | O37: VIP Reseller | P37: Database (Supabase) & VIP Reseller | Q37: 2026-10-02 21:15
A38: 34 | B38: vip-vidiosharedmbl1bln-s2 | C38: VIDIOSHAREDMBL1BLN-S2 | D38: Vidio Platinum - Video Premier Platinum [ 1 Bulan ] [ Shared 2 User - 1 Devices - Khusus Mobile] | E38: Apps & Streaming | F38: Apps & Streaming | G38: Sharing | H38: Aktif | I38: Tersedia | J38: 15000 | K38: 19500 | L38: Video Premier Platinum [ 1 Bulan ] [ Shared 2 User - 1 Devices - Khusus Mobile] - Layanan digital resmi terverifikasi dengan aktivasi instan. | M38: 1 Bulan | O38: VIP Reseller | P38: Database (Supabase) & VIP Reseller | Q38: 2026-10-02 21:15
A39: 35 | B39: vip-viu1thngar3bln-s1 | C39: VIU1THNGAR3BLN-S1 | D39: VIU Private 12 Bulan [ AKUN - 1 DEVICES ] [GARANSI 3 BULAN] | E39: Apps & Streaming | F39: Apps & Streaming | G39: Private | H39: Aktif | I39: Tersedia | J39: 6500 | K39: 12000 | L39: Private 12 Bulan [ AKUN - 1 DEVICES ] [GARANSI 3 BULAN] - Layanan digital resmi terverifikasi dengan aktivasi instan. | M39: 1 Tahun | N39: GARANSI 3 BULAN | O39: VIP Reseller | P39: Database (Supabase) & VIP Reseller | Q39: 2026-10-02 21:15
A40: 36 | B40: vip-wetvprivate1bln-s1 | C40: WETVPRIVATE1BLN-S1 | D40: WETV Premium [ 1 Bulan ] [ Private ] | E40: Apps & Streaming | F40: Apps & Streaming | G40: Private | H40: Aktif | I40: Tersedia | J40: 30000 | K40: 33000 | L40: WETV Premium [ 1 Bulan ] [ Private ] - Layanan digital resmi terverifikasi dengan aktivasi instan. | M40: 1 Bulan | O40: VIP Reseller | P40: Database (Supabase) & VIP Reseller | Q40: 2026-10-02 21:15
A41: 37 | B41: vip-wetvshared1bln-s2 | C41: WETVSHARED1BLN-S2 | D41: WETV Premium [ 1 Bulan] [ Shared - 1 Devices ] | E41: Apps & Streaming | F41: Apps & Streaming | G41: Sharing | H41: Aktif | I41: Tersedia | J41: 8500 | K41: 12000 | L41: WETV Premium [ 1 Bulan] [ Shared - 1 Devices ] - Layanan digital resmi terverifikasi dengan aktivasi instan. | M41: 1 Bulan | O41: VIP Reseller | P41: Database (Supabase) & VIP Reseller | Q41: 2026-10-02 21:15
...

Sheet PRICING_ANALYSIS
A1: ASTERRA STORE — ANALISIS PRICING, MARGIN & DISTRIBUSI PENDAPATAN
A2: Formula Dasar: Gross Profit = Selling - Cost | Minimum Profit = Rp3.000 | Sales Commission Baseline = 10% | Promo Customer = 5% (Maks. Rp5.000) ditanggung CEO 50% & COO 50%
A4: No | B4: Product ID | C4: Product Name | D4: Category | E4: Cost Price | F4: Current Selling Price | G4: Gross Profit | H4: Gross Margin % | I4: Markup % | J4: Minimum Gross Profit | K4: Minimum Selling Price | L4: Pricing Status | M4: Pricing Type | N4: Sales Commission % | O4: CEO % | P4: COO % | Q4: Sales Commission Amount | R4: CEO Gross Share | S4: COO Gross Share | T4: Promo % | U4: Maximum Discount | V4: Actual Discount | W4: CEO Promo Burden | X4: COO Promo Burden | Y4: CEO Final Income | Z4: COO Final Income | AA4: Sales Final Income | AB4: Profit After Promo | AC4: Review Flag | AD4: Notes
A5: =ACTIVE_PRODUCTS_RAW!A5 | B5: =ACTIVE_PRODUCTS_RAW!B5 | C5: =ACTIVE_PRODUCTS_RAW!D5 | D5: =ACTIVE_PRODUCTS_RAW!E5 | E5: =ACTIVE_PRODUCTS_RAW!J5 | F5: =ACTIVE_PRODUCTS_RAW!K5 | G5: =F5-E5 | H5: =G5/F5 | I5: =G5/E5 | J5: 3000 | K5: =E5+J5 | L5: =IF(G5>=J5,"MEETS MINIMUM","BELOW MINIMUM") | M5: STANDARD | N5: 0.1 | O5: =(1-N5)/2 | P5: =(1-N5)/2 | Q5: =G5*N5 | R5: =(G5-Q5)/2 | S5: =(G5-Q5)/2 | T5: 0.05 | U5: 5000 | V5: =MIN(F5*T5, U5) | W5: =V5*0.5 | X5: =V5*0.5 | Y5: =R5-W5 | Z5: =S5-X5 | AA5: =Q5 | AB5: =G5-V5 | AC5: =IF(M5="MANUAL","MANUAL REVIEW",IF(G5<J5,"BELOW MINIMUM",IF(Y5<0,"NEGATIVE CEO SHARE","OK"))) | AD5: Margin sehat memenuhi target laba minimum Asterra (>= Rp3.000).
A6: =ACTIVE_PRODUCTS_RAW!A6 | B6: =ACTIVE_PRODUCTS_RAW!B6 | C6: =ACTIVE_PRODUCTS_RAW!D6 | D6: =ACTIVE_PRODUCTS_RAW!E6 | E6: =ACTIVE_PRODUCTS_RAW!J6 | F6: =ACTIVE_PRODUCTS_RAW!K6 | G6: =F6-E6 | H6: =G6/F6 | I6: =G6/E6 | J6: 3000 | K6: =E6+J6 | L6: =IF(G6>=J6,"MEETS MINIMUM","BELOW MINIMUM") | M6: STANDARD | N6: 0.1 | O6: =(1-N6)/2 | P6: =(1-N6)/2 | Q6: =G6*N6 | R6: =(G6-Q6)/2 | S6: =(G6-Q6)/2 | T6: 0.05 | U6: 5000 | V6: =MIN(F6*T6, U6) | W6: =V6*0.5 | X6: =V6*0.5 | Y6: =R6-W6 | Z6: =S6-X6 | AA6: =Q6 | AB6: =G6-V6 | AC6: =IF(M6="MANUAL","MANUAL REVIEW",IF(G6<J6,"BELOW MINIMUM",IF(Y6<0,"NEGATIVE CEO SHARE","OK"))) | AD6: Margin sehat memenuhi target laba minimum Asterra (>= Rp3.000).
A7: =ACTIVE_PRODUCTS_RAW!A7 | B7: =ACTIVE_PRODUCTS_RAW!B7 | C7: =ACTIVE_PRODUCTS_RAW!D7 | D7: =ACTIVE_PRODUCTS_RAW!E7 | E7: =ACTIVE_PRODUCTS_RAW!J7 | F7: =ACTIVE_PRODUCTS_RAW!K7 | G7: =F7-E7 | H7: =G7/F7 | I7: =G7/E7 | J7: 3000 | K7: =E7+J7 | L7: =IF(G7>=J7,"MEETS MINIMUM","BELOW MINIMUM") | M7: MANUAL | N7: 0.1 | O7: =(1-N7)/2 | P7: =(1-N7)/2 | Q7: =G7*N7 | R7: =(G7-Q7)/2 | S7: =(G7-Q7)/2 | T7: 0.05 | U7: 5000 | V7: =MIN(F7*T7, U7) | W7: =V7*0.5 | X7: =V7*0.5 | Y7: =R7-W7 | Z7: =S7-X7 | AA7: =Q7 | AB7: =G7-V7 | AC7: =IF(M7="MANUAL","MANUAL REVIEW",IF(G7<J7,"BELOW MINIMUM",IF(Y7<0,"NEGATIVE CEO SHARE","OK"))) | AD7: Target Price Ladder Asterra: Rp25.000 (Sesuai patokan resmi; profit Rp12.000).
A8: =ACTIVE_PRODUCTS_RAW!A8 | B8: =ACTIVE_PRODUCTS_RAW!B8 | C8: =ACTIVE_PRODUCTS_RAW!D8 | D8: =ACTIVE_PRODUCTS_RAW!E8 | E8: =ACTIVE_PRODUCTS_RAW!J8 | F8: =ACTIVE_PRODUCTS_RAW!K8 | G8: =F8-E8 | H8: =G8/F8 | I8: =G8/E8 | J8: 3000 | K8: =E8+J8 | L8: =IF(G8>=J8,"MEETS MINIMUM","BELOW MINIMUM") | M8: MANUAL | N8: 0.1 | O8: =(1-N8)/2 | P8: =(1-N8)/2 | Q8: =G8*N8 | R8: =(G8-Q8)/2 | S8: =(G8-Q8)/2 | T8: 0.05 | U8: 5000 | V8: =MIN(F8*T8, U8) | W8: =V8*0.5 | X8: =V8*0.5 | Y8: =R8-W8 | Z8: =S8-X8 | AA8: =Q8 | AB8: =G8-V8 | AC8: =IF(M8="MANUAL","MANUAL REVIEW",IF(G8<J8,"BELOW MINIMUM",IF(Y8<0,"NEGATIVE CEO SHARE","OK"))) | AD8: Target Price Ladder Asterra: Rp60.000 (Saat ini di web Rp21.000; tinjau update live CMS/DB).
A9: =ACTIVE_PRODUCTS_RAW!A9 | B9: =ACTIVE_PRODUCTS_RAW!B9 | C9: =ACTIVE_PRODUCTS_RAW!D9 | D9: =ACTIVE_PRODUCTS_RAW!E9 | E9: =ACTIVE_PRODUCTS_RAW!J9 | F9: =ACTIVE_PRODUCTS_RAW!K9 | G9: =F9-E9 | H9: =G9/F9 | I9: =G9/E9 | J9: 3000 | K9: =E9+J9 | L9: =IF(G9>=J9,"MEETS MINIMUM","BELOW MINIMUM") | M9: MANUAL | N9: 0.1 | O9: =(1-N9)/2 | P9: =(1-N9)/2 | Q9: =G9*N9 | R9: =(G9-Q9)/2 | S9: =(G9-Q9)/2 | T9: 0.05 | U9: 5000 | V9: =MIN(F9*T9, U9) | W9: =V9*0.5 | X9: =V9*0.5 | Y9: =R9-W9 | Z9: =S9-X9 | AA9: =Q9 | AB9: =G9-V9 | AC9: =IF(M9="MANUAL","MANUAL REVIEW",IF(G9<J9,"BELOW MINIMUM",IF(Y9<0,"NEGATIVE CEO SHARE","OK"))) | AD9: Target Price Ladder Asterra: Rp100.000 (Saat ini di web Rp31.000; tinjau update live CMS/DB).
A10: =ACTIVE_PRODUCTS_RAW!A10 | B10: =ACTIVE_PRODUCTS_RAW!B10 | C10: =ACTIVE_PRODUCTS_RAW!D10 | D10: =ACTIVE_PRODUCTS_RAW!E10 | E10: =ACTIVE_PRODUCTS_RAW!J10 | F10: =ACTIVE_PRODUCTS_RAW!K10 | G10: =F10-E10 | H10: =G10/F10 | I10: =G10/E10 | J10: 3000 | K10: =E10+J10 | L10: =IF(G10>=J10,"MEETS MINIMUM","BELOW MINIMUM") | M10: MANUAL | N10: 0.1 | O10: =(1-N10)/2 | P10: =(1-N10)/2 | Q10: =G10*N10 | R10: =(G10-Q10)/2 | S10: =(G10-Q10)/2 | T10: 0.05 | U10: 5000 | V10: =MIN(F10*T10, U10) | W10: =V10*0.5 | X10: =V10*0.5 | Y10: =R10-W10 | Z10: =S10-X10 | AA10: =Q10 | AB10: =G10-V10 | AC10: =IF(M10="MANUAL","MANUAL REVIEW",IF(G10<J10,"BELOW MINIMUM",IF(Y10<0,"NEGATIVE CEO SHARE","OK"))) | AD10: Paket manual Gemini Pro / Google AI; pertahankan price ladder resmi Asterra.
A11: =ACTIVE_PRODUCTS_RAW!A11 | B11: =ACTIVE_PRODUCTS_RAW!B11 | C11: =ACTIVE_PRODUCTS_RAW!D11 | D11: =ACTIVE_PRODUCTS_RAW!E11 | E11: =ACTIVE_PRODUCTS_RAW!J11 | F11: =ACTIVE_PRODUCTS_RAW!K11 | G11: =F11-E11 | H11: =G11/F11 | I11: =G11/E11 | J11: 3000 | K11: =E11+J11 | L11: =IF(G11>=J11,"MEETS MINIMUM","BELOW MINIMUM") | M11: MANUAL | N11: 0.1 | O11: =(1-N11)/2 | P11: =(1-N11)/2 | Q11: =G11*N11 | R11: =(G11-Q11)/2 | S11: =(G11-Q11)/2 | T11: 0.05 | U11: 5000 | V11: =MIN(F11*T11, U11) | W11: =V11*0.5 | X11: =V11*0.5 | Y11: =R11-W11 | Z11: =S11-X11 | AA11: =Q11 | AB11: =G11-V11 | AC11: =IF(M11="MANUAL","MANUAL REVIEW",IF(G11<J11,"BELOW MINIMUM",IF(Y11<0,"NEGATIVE CEO SHARE","OK"))) | AD11: Paket manual Gemini Pro / Google AI; pertahankan price ladder resmi Asterra.
A12: =ACTIVE_PRODUCTS_RAW!A12 | B12: =ACTIVE_PRODUCTS_RAW!B12 | C12: =ACTIVE_PRODUCTS_RAW!D12 | D12: =ACTIVE_PRODUCTS_RAW!E12 | E12: =ACTIVE_PRODUCTS_RAW!J12 | F12: =ACTIVE_PRODUCTS_RAW!K12 | G12: =F12-E12 | H12: =G12/F12 | I12: =G12/E12 | J12: 3000 | K12: =E12+J12 | L12: =IF(G12>=J12,"MEETS MINIMUM","BELOW MINIMUM") | M12: MANUAL | N12: 0.1 | O12: =(1-N12)/2 | P12: =(1-N12)/2 | Q12: =G12*N12 | R12: =(G12-Q12)/2 | S12: =(G12-Q12)/2 | T12: 0.05 | U12: 5000 | V12: =MIN(F12*T12, U12) | W12: =V12*0.5 | X12: =V12*0.5 | Y12: =R12-W12 | Z12: =S12-X12 | AA12: =Q12 | AB12: =G12-V12 | AC12: =IF(M12="MANUAL","MANUAL REVIEW",IF(G12<J12,"BELOW MINIMUM",IF(Y12<0,"NEGATIVE CEO SHARE","OK"))) | AD12: Paket manual Gemini Pro / Google AI; pertahankan price ladder resmi Asterra.
A13: =ACTIVE_PRODUCTS_RAW!A13 | B13: =ACTIVE_PRODUCTS_RAW!B13 | C13: =ACTIVE_PRODUCTS_RAW!D13 | D13: =ACTIVE_PRODUCTS_RAW!E13 | E13: =ACTIVE_PRODUCTS_RAW!J13 | F13: =ACTIVE_PRODUCTS_RAW!K13 | G13: =F13-E13 | H13: =G13/F13 | I13: =G13/E13 | J13: 3000 | K13: =E13+J13 | L13: =IF(G13>=J13,"MEETS MINIMUM","BELOW MINIMUM") | M13: MANUAL | N13: 0.1 | O13: =(1-N13)/2 | P13: =(1-N13)/2 | Q13: =G13*N13 | R13: =(G13-Q13)/2 | S13: =(G13-Q13)/2 | T13: 0.05 | U13: 5000 | V13: =MIN(F13*T13, U13) | W13: =V13*0.5 | X13: =V13*0.5 | Y13: =R13-W13 | Z13: =S13-X13 | AA13: =Q13 | AB13: =G13-V13 | AC13: =IF(M13="MANUAL","MANUAL REVIEW",IF(G13<J13,"BELOW MINIMUM",IF(Y13<0,"NEGATIVE CEO SHARE","OK"))) | AD13: Paket manual Gemini Pro / Google AI; pertahankan price ladder resmi Asterra.
A14: =ACTIVE_PRODUCTS_RAW!A14 | B14: =ACTIVE_PRODUCTS_RAW!B14 | C14: =ACTIVE_PRODUCTS_RAW!D14 | D14: =ACTIVE_PRODUCTS_RAW!E14 | E14: =ACTIVE_PRODUCTS_RAW!J14 | F14: =ACTIVE_PRODUCTS_RAW!K14 | G14: =F14-E14 | H14: =G14/F14 | I14: =G14/E14 | J14: 3000 | K14: =E14+J14 | L14: =IF(G14>=J14,"MEETS MINIMUM","BELOW MINIMUM") | M14: STANDARD | N14: 0.1 | O14: =(1-N14)/2 | P14: =(1-N14)/2 | Q14: =G14*N14 | R14: =(G14-Q14)/2 | S14: =(G14-Q14)/2 | T14: 0.05 | U14: 5000 | V14: =MIN(F14*T14, U14) | W14: =V14*0.5 | X14: =V14*0.5 | Y14: =R14-W14 | Z14: =S14-X14 | AA14: =Q14 | AB14: =G14-V14 | AC14: =IF(M14="MANUAL","MANUAL REVIEW",IF(G14<J14,"BELOW MINIMUM",IF(Y14<0,"NEGATIVE CEO SHARE","OK"))) | AD14: Margin sehat memenuhi target laba minimum Asterra (>= Rp3.000).
A15: =ACTIVE_PRODUCTS_RAW!A15 | B15: =ACTIVE_PRODUCTS_RAW!B15 | C15: =ACTIVE_PRODUCTS_RAW!D15 | D15: =ACTIVE_PRODUCTS_RAW!E15 | E15: =ACTIVE_PRODUCTS_RAW!J15 | F15: =ACTIVE_PRODUCTS_RAW!K15 | G15: =F15-E15 | H15: =G15/F15 | I15: =G15/E15 | J15: 3000 | K15: =E15+J15 | L15: =IF(G15>=J15,"MEETS MINIMUM","BELOW MINIMUM") | M15: STANDARD | N15: 0.1 | O15: =(1-N15)/2 | P15: =(1-N15)/2 | Q15: =G15*N15 | R15: =(G15-Q15)/2 | S15: =(G15-Q15)/2 | T15: 0.05 | U15: 5000 | V15: =MIN(F15*T15, U15) | W15: =V15*0.5 | X15: =V15*0.5 | Y15: =R15-W15 | Z15: =S15-X15 | AA15: =Q15 | AB15: =G15-V15 | AC15: =IF(M15="MANUAL","MANUAL REVIEW",IF(G15<J15,"BELOW MINIMUM",IF(Y15<0,"NEGATIVE CEO SHARE","OK"))) | AD15: Margin sehat memenuhi target laba minimum Asterra (>= Rp3.000).
A16: =ACTIVE_PRODUCTS_RAW!A16 | B16: =ACTIVE_PRODUCTS_RAW!B16 | C16: =ACTIVE_PRODUCTS_RAW!D16 | D16: =ACTIVE_PRODUCTS_RAW!E16 | E16: =ACTIVE_PRODUCTS_RAW!J16 | F16: =ACTIVE_PRODUCTS_RAW!K16 | G16: =F16-E16 | H16: =G16/F16 | I16: =G16/E16 | J16: 3000 | K16: =E16+J16 | L16: =IF(G16>=J16,"MEETS MINIMUM","BELOW MINIMUM") | M16: STANDARD | N16: 0.1 | O16: =(1-N16)/2 | P16: =(1-N16)/2 | Q16: =G16*N16 | R16: =(G16-Q16)/2 | S16: =(G16-Q16)/2 | T16: 0.05 | U16: 5000 | V16: =MIN(F16*T16, U16) | W16: =V16*0.5 | X16: =V16*0.5 | Y16: =R16-W16 | Z16: =S16-X16 | AA16: =Q16 | AB16: =G16-V16 | AC16: =IF(M16="MANUAL","MANUAL REVIEW",IF(G16<J16,"BELOW MINIMUM",IF(Y16<0,"NEGATIVE CEO SHARE","OK"))) | AD16: Margin sehat memenuhi target laba minimum Asterra (>= Rp3.000).
... A41: =ACTIVE_PRODUCTS_RAW!A41 | B41: =ACTIVE_PRODUCTS_RAW!B41 | C41: =ACTIVE_PRODUCTS_RAW!D41 | D41: =ACTIVE_PRODUCTS_RAW!E41 | E41: =ACTIVE_PRODUCTS_RAW!J41 | F41: =ACTIVE_PRODUCTS_RAW!K41 | G41: =F41-E41 | H41: =G41/F41 | I41: =G41/E41 | J41: 3000 | K41: =E41+J41 | L41: =IF(G41>=J41,"MEETS MINIMUM","BELOW MINIMUM") | M41: STANDARD | N41: 0.1 | O41: =(1-N41)/2 | P41: =(1-N41)/2 | Q41: =G41*N41 | R41: =(G41-Q41)/2 | S41: =(G41-Q41)/2 | T41: 0.05 | U41: 5000 | V41: =MIN(F41*T41, U41) | W41: =V41*0.5 | X41: =V41*0.5 | Y41: =R41-W41 | Z41: =S41-X41 | AA41: =Q41 | AB41: =G41-V41 | AC41: =IF(M41="MANUAL","MANUAL REVIEW",IF(G41<J41,"BELOW MINIMUM",IF(Y41<0,"NEGATIVE CEO SHARE","OK"))) | AD41: Margin sehat memenuhi target laba minimum Asterra (>= Rp3.000).
A42: RATA-RATA / TOTAL | E42: =AVERAGE(E5:E41) | F42: =AVERAGE(F5:F41) | G42: =AVERAGE(G5:G41) | H42: =AVERAGE(H5:H41) | I42: =AVERAGE(I5:I41) | J42: =AVERAGE(J5:J41) | K42: =AVERAGE(K5:K41) | Q42: =AVERAGE(Q5:Q41) | R42: =AVERAGE(R5:R41) | S42: =AVERAGE(S5:S41) | V42: =AVERAGE(V5:V41) | W42: =AVERAGE(W5:W41) | X42: =AVERAGE(X5:X41) | Y42: =AVERAGE(Y5:Y41) | Z42: =AVERAGE(Z5:Z41) | AA42: =AVERAGE(AA5:AA41) | AB42: =AVERAGE(AB5:AB41)

Sheet COMMISSION_ANALYSIS
A1: ASTERRA STORE — SIMULASI KOMISI SALES LENGKAP (10% - 15%)
A2: Simulasi Nominal Komisi Sales (10%, 11%, 12%, 13%, 14%, 15% dari Gross Profit) & Sisa Gross Profit untuk CEO/COO | Status Rekomendasi: TBD
A4: No | B4: Product ID | C4: Product Name | D4: Category | E4: Selling Price | F4: Cost Price | G4: Gross Profit | H4: Sales 10% (Rp) | I4: Sales 11% (Rp) | J4: Sales 12% (Rp) | K4: Sales 13% (Rp) | L4: Sales 14% (Rp) | M4: Sales 15% (Rp) | N4: CEO Share @10% | O4: CEO Share @15% | P4: Recommended Sales Commission | Q4: Notes
A5: =PRICING_ANALYSIS!A5 | B5: =PRICING_ANALYSIS!B5 | C5: =PRICING_ANALYSIS!C5 | D5: =PRICING_ANALYSIS!D5 | E5: =PRICING_ANALYSIS!F5 | F5: =PRICING_ANALYSIS!E5 | G5: =E5-F5 | H5: =G5*0.10 | I5: =G5*0.11 | J5: =G5*0.12 | K5: =G5*0.13 | L5: =G5*0.14 | M5: =G5*0.15 | N5: =(G5-H5)/2 | O5: =(G5-M5)/2 | P5: TBD | Q5: Menunggu penetapan final rate dari manajemen Asterra Store
A6: =PRICING_ANALYSIS!A6 | B6: =PRICING_ANALYSIS!B6 | C6: =PRICING_ANALYSIS!C6 | D6: =PRICING_ANALYSIS!D6 | E6: =PRICING_ANALYSIS!F6 | F6: =PRICING_ANALYSIS!E6 | G6: =E6-F6 | H6: =G6*0.10 | I6: =G6*0.11 | J6: =G6*0.12 | K6: =G6*0.13 | L6: =G6*0.14 | M6: =G6*0.15 | N6: =(G6-H6)/2 | O6: =(G6-M6)/2 | P6: TBD | Q6: Menunggu penetapan final rate dari manajemen Asterra Store
A7: =PRICING_ANALYSIS!A7 | B7: =PRICING_ANALYSIS!B7 | C7: =PRICING_ANALYSIS!C7 | D7: =PRICING_ANALYSIS!D7 | E7: =PRICING_ANALYSIS!F7 | F7: =PRICING_ANALYSIS!E7 | G7: =E7-F7 | H7: =G7*0.10 | I7: =G7*0.11 | J7: =G7*0.12 | K7: =G7*0.13 | L7: =G7*0.14 | M7: =G7*0.15 | N7: =(G7-H7)/2 | O7: =(G7-M7)/2 | P7: TBD | Q7: Menunggu penetapan final rate dari manajemen Asterra Store
A8: =PRICING_ANALYSIS!A8 | B8: =PRICING_ANALYSIS!B8 | C8: =PRICING_ANALYSIS!C8 | D8: =PRICING_ANALYSIS!D8 | E8: =PRICING_ANALYSIS!F8 | F8: =PRICING_ANALYSIS!E8 | G8: =E8-F8 | H8: =G8*0.10 | I8: =G8*0.11 | J8: =G8*0.12 | K8: =G8*0.13 | L8: =G8*0.14 | M8: =G8*0.15 | N8: =(G8-H8)/2 | O8: =(G8-M8)/2 | P8: TBD | Q8: Menunggu penetapan final rate dari manajemen Asterra Store
A9: =PRICING_ANALYSIS!A9 | B9: =PRICING_ANALYSIS!B9 | C9: =PRICING_ANALYSIS!C9 | D9: =PRICING_ANALYSIS!D9 | E9: =PRICING_ANALYSIS!F9 | F9: =PRICING_ANALYSIS!E9 | G9: =E9-F9 | H9: =G9*0.10 | I9: =G9*0.11 | J9: =G9*0.12 | K9: =G9*0.13 | L9: =G9*0.14 | M9: =G9*0.15 | N9: =(G9-H9)/2 | O9: =(G9-M9)/2 | P9: TBD | Q9: Menunggu penetapan final rate dari manajemen Asterra Store
A10: =PRICING_ANALYSIS!A10 | B10: =PRICING_ANALYSIS!B10 | C10: =PRICING_ANALYSIS!C10 | D10: =PRICING_ANALYSIS!D10 | E10: =PRICING_ANALYSIS!F10 | F10: =PRICING_ANALYSIS!E10 | G10: =E10-F10 | H10: =G10*0.10 | I10: =G10*0.11 | J10: =G10*0.12 | K10: =G10*0.13 | L10: =G10*0.14 | M10: =G10*0.15 | N10: =(G10-H10)/2 | O10: =(G10-M10)/2 | P10: TBD | Q10: Menunggu penetapan final rate dari manajemen Asterra Store
A11: =PRICING_ANALYSIS!A11 | B11: =PRICING_ANALYSIS!B11 | C11: =PRICING_ANALYSIS!C11 | D11: =PRICING_ANALYSIS!D11 | E11: =PRICING_ANALYSIS!F11 | F11: =PRICING_ANALYSIS!E11 | G11: =E11-F11 | H11: =G11*0.10 | I11: =G11*0.11 | J11: =G11*0.12 | K11: =G11*0.13 | L11: =G11*0.14 | M11: =G11*0.15 | N11: =(G11-H11)/2 | O11: =(G11-M11)/2 | P11: TBD | Q11: Menunggu penetapan final rate dari manajemen Asterra Store
A12: =PRICING_ANALYSIS!A12 | B12: =PRICING_ANALYSIS!B12 | C12: =PRICING_ANALYSIS!C12 | D12: =PRICING_ANALYSIS!D12 | E12: =PRICING_ANALYSIS!F12 | F12: =PRICING_ANALYSIS!E12 | G12: =E12-F12 | H12: =G12*0.10 | I12: =G12*0.11 | J12: =G12*0.12 | K12: =G12*0.13 | L12: =G12*0.14 | M12: =G12*0.15 | N12: =(G12-H12)/2 | O12: =(G12-M12)/2 | P12: TBD | Q12: Menunggu penetapan final rate dari manajemen Asterra Store
A13: =PRICING_ANALYSIS!A13 | B13: =PRICING_ANALYSIS!B13 | C13: =PRICING_ANALYSIS!C13 | D13: =PRICING_ANALYSIS!D13 | E13: =PRICING_ANALYSIS!F13 | F13: =PRICING_ANALYSIS!E13 | G13: =E13-F13 | H13: =G13*0.10 | I13: =G13*0.11 | J13: =G13*0.12 | K13: =G13*0.13 | L13: =G13*0.14 | M13: =G13*0.15 | N13: =(G13-H13)/2 | O13: =(G13-M13)/2 | P13: TBD | Q13: Menunggu penetapan final rate dari manajemen Asterra Store
A14: =PRICING_ANALYSIS!A14 | B14: =PRICING_ANALYSIS!B14 | C14: =PRICING_ANALYSIS!C14 | D14: =PRICING_ANALYSIS!D14 | E14: =PRICING_ANALYSIS!F14 | F14: =PRICING_ANALYSIS!E14 | G14: =E14-F14 | H14: =G14*0.10 | I14: =G14*0.11 | J14: =G14*0.12 | K14: =G14*0.13 | L14: =G14*0.14 | M14: =G14*0.15 | N14: =(G14-H14)/2 | O14: =(G14-M14)/2 | P14: TBD | Q14: Menunggu penetapan final rate dari manajemen Asterra Store
A15: =PRICING_ANALYSIS!A15 | B15: =PRICING_ANALYSIS!B15 | C15: =PRICING_ANALYSIS!C15 | D15: =PRICING_ANALYSIS!D15 | E15: =PRICING_ANALYSIS!F15 | F15: =PRICING_ANALYSIS!E15 | G15: =E15-F15 | H15: =G15*0.10 | I15: =G15*0.11 | J15: =G15*0.12 | K15: =G15*0.13 | L15: =G15*0.14 | M15: =G15*0.15 | N15: =(G15-H15)/2 | O15: =(G15-M15)/2 | P15: TBD | Q15: Menunggu penetapan final rate dari manajemen Asterra Store
A16: =PRICING_ANALYSIS!A16 | B16: =PRICING_ANALYSIS!B16 | C16: =PRICING_ANALYSIS!C16 | D16: =PRICING_ANALYSIS!D16 | E16: =PRICING_ANALYSIS!F16 | F16: =PRICING_ANALYSIS!E16 | G16: =E16-F16 | H16: =G16*0.10 | I16: =G16*0.11 | J16: =G16*0.12 | K16: =G16*0.13 | L16: =G16*0.14 | M16: =G16*0.15 | N16: =(G16-H16)/2 | O16: =(G16-M16)/2 | P16: TBD | Q16: Menunggu penetapan final rate dari manajemen Asterra Store
... A41: =PRICING_ANALYSIS!A41 | B41: =PRICING_ANALYSIS!B41 | C41: =PRICING_ANALYSIS!C41 | D41: =PRICING_ANALYSIS!D41 | E41: =PRICING_ANALYSIS!F41 | F41: =PRICING_ANALYSIS!E41 | G41: =E41-F41 | H41: =G41*0.10 | I41: =G41*0.11 | J41: =G41*0.12 | K41: =G41*0.13 | L41: =G41*0.14 | M41: =G41*0.15 | N41: =(G41-H41)/2 | O41: =(G41-M41)/2 | P41: TBD | Q41: Menunggu penetapan final rate dari manajemen Asterra Store
A42: RATA-RATA | E42: =AVERAGE(E5:E41) | F42: =AVERAGE(F5:F41) | G42: =AVERAGE(G5:G41) | H42: =AVERAGE(H5:H41) | I42: =AVERAGE(I5:I41) | J42: =AVERAGE(J5:J41) | K42: =AVERAGE(K5:K41) | L42: =AVERAGE(L5:L41) | ... O42: =AVERAGE(O5:O41)

Sheet COMMISSION_RULES
A1: ASTERRA STORE — ATURAN & SISTEM KOMISI SALES & PROMO
A2: Pedoman Operasional Pembagian Laba, Peran Sales, dan Alokasi Beban Diskon Promo
A4: 1. PRINSIP DASAR & PERAN SALES ASTERRA STORE
A5: • Sales BUKAN Reseller: Sales tidak membeli produk untuk dijual kembali dan tidak menentukan harga jual secara mandiri.
A6: • Transaksi Langsung: Customer bertransaksi dan membayar langsung melalui website resmi Asterra Store.
A7: • Promosi Melalui Kode Unik: Sales mempromosikan website menggunakan kode promo khusus Sales.
A8: • Hak Komisi: Sales mendapatkan komisi persentase dari Gross Profit (Laba Kotor), BUKAN dari Omzet (Gross Revenue).
A9: • Tanpa Kode Sales: Jika customer order tanpa kode Sales, Laba Kotor dibagi rata: CEO 50% & COO 50% (Sales 0%).
A10: • Dengan Kode Sales: Sales mendapatkan komisi 10% - 15% dari Gross Profit. Sisa laba dibagi rata: CEO (100%-Sales%)/2 dan COO (100%-Sales%)/2.
A12: 2. MATRIKS DISTRIBUSI LABA KOTOR (GROSS PROFIT)
A13: Skenario | B13: Komisi Sales (%) | C13: Porsi CEO (%) | D13: Porsi COO (%) | E13: Keterangan
A14: Tanpa Kode Sales | B14: 0 | C14: 0.5 | D14: 0.5 | E14: Seluruh laba kotor dibagi rata CEO dan COO 50:50
A15: Dengan Kode Sales (10%) | B15: 0.1 | C15: 0.45 | D15: 0.45 | E15: Sales 10%, sisa 90% dibagi rata CEO 45% & COO 45%
A16: Dengan Kode Sales (11%) | B16: 0.11 | C16: 0.445 | D16: 0.445 | E16: Sales 11%, sisa 89% dibagi rata CEO 44.5% & COO 44.5%
A17: Dengan Kode Sales (12%) | B17: 0.12 | C17: 0.44 | D17: 0.44 | E17: Sales 12%, sisa 88% dibagi rata CEO 44.0% & COO 44.0%
A18: Dengan Kode Sales (13%) | B18: 0.13 | C18: 0.435 | D18: 0.435 | E18: Sales 13%, sisa 87% dibagi rata CEO 43.5% & COO 43.5%
A19: Dengan Kode Sales (14%) | B19: 0.14 | C19: 0.43 | D19: 0.43 | E19: Sales 14%, sisa 86% dibagi rata CEO 43.0% & COO 43.0%
A20: Dengan Kode Sales (15%) | B20: 0.15 | C20: 0.425 | D20: 0.425 | E20: Sales 15%, sisa 85% dibagi rata CEO 42.5% & COO 42.5%
A23: 3. KEBIJAKAN PROMO SALES & BEBAN DISKON
A24: • Besaran Diskon Customer: Kode promo Sales memberikan diskon 5% dengan batas maksimal Rp5.000.
A25: • Formula Diskon: Actual Discount = MIN(Selling Price × 5%, Rp5.000).
A26: • Beban Diskon 100% Ditanggung Manajemen: CEO menanggung 50% dan COO menanggung 50% dari diskon aktual.
A27: • Komisi Sales Kebal Diskon: Sales TIDAK menanggung diskon sama sekali (Sales Promo Burden = Rp0). Komisi Sales tetap dihitung penuh dari Gross Profit awal.
A28: • Wording Resmi Promo ke Customer: 'Gunakan kode promo untuk mendapatkan diskon 5% (maks. Rp5.000)'.
A30: 4. URUTAN KALKULASI & CONTOH STUDI KASUS NYATA
A31: 1. Selling Price = Rp100.000 | Cost Price = Rp70.000
A32: 2. Gross Profit = Rp100.000 - Rp70.000 = Rp30.000
A33: 3. Sales Commission Rate = 15%
A34: 4. Sales Commission Amount = 15% × Rp30.000 = Rp4.500
A35: 5. Sisa Gross Profit = Rp30.000 - Rp4.500 = Rp25.500
... A42: 12. Total Profit Bisnis Setelah Promo = Rp10.250 + Rp10.250 + Rp4.500 = Rp25.000 (Tepat sama dengan Gross Profit Rp30.000 - Diskon Rp5.000)

Sheet PROMO_SIMULATION
A1: ASTERRA STORE — SIMULASI DAMPAK DISKON PROMO SALES (5% MAKS. RP5.000)
A2: Simulasi Diskon Customer 5% (Maks. Rp5.000) Ditanggung 50% CEO & 50% COO | Sales Tetap Menerima Komisi Penuh
A4: No | B4: Product ID | C4: Product Name | D4: Selling Price | E4: Cost Price | F4: Gross Profit | G4: Promo Rate | H4: Max Discount Cap | I4: Customer Discount | J4: Net Price Paid | K4: Sales Comm @10% | L4: Sales Comm @15% | M4: CEO Discount Burden | N4: COO Discount Burden | O4: CEO Net Income (@10% Sales) | P4: CEO Net Income (@15% Sales) | Q4: COO Net Income (@10% Sales) | R4: COO Net Income (@15% Sales) | S4: Net Profit After Promo | T4: Promo Viability Status | U4: Strategic Recommendation
A5: =PRICING_ANALYSIS!A5 | B5: =PRICING_ANALYSIS!B5 | C5: =PRICING_ANALYSIS!C5 | D5: =PRICING_ANALYSIS!F5 | E5: =PRICING_ANALYSIS!E5 | F5: =D5-E5 | G5: 0.05 | H5: 5000 | I5: =MIN(D5*G5, H5) | J5: =D5-I5 | K5: =F5*0.10 | L5: =F5*0.15 | M5: =I5*0.5 | N5: =I5*0.5 | O5: =((F5-K5)/2)-M5 | P5: =((F5-L5)/2)-M5 | Q5: =((F5-K5)/2)-N5 | R5: =((F5-L5)/2)-N5 | S5: =F5-I5 | T5: =IF(P5<=0,"DEFICIT RISK",IF(P5<1000,"TIGHT MARGIN","HEALTHY")) | U5: Laba CEO/COO setelah promo tipis (< Rp1.000); rekomendasikan komisi Sales maksimal 10% untuk menjaga profitabilitas.
A6: =PRICING_ANALYSIS!A6 | B6: =PRICING_ANALYSIS!B6 | C6: =PRICING_ANALYSIS!C6 | D6: =PRICING_ANALYSIS!F6 | E6: =PRICING_ANALYSIS!E6 | F6: =D6-E6 | G6: 0.05 | H6: 5000 | I6: =MIN(D6*G6, H6) | J6: =D6-I6 | K6: =F6*0.10 | L6: =F6*0.15 | M6: =I6*0.5 | N6: =I6*0.5 | O6: =((F6-K6)/2)-M6 | P6: =((F6-L6)/2)-M6 | Q6: =((F6-K6)/2)-N6 | R6: =((F6-L6)/2)-N6 | S6: =F6-I6 | T6: =IF(P6<=0,"DEFICIT RISK",IF(P6<1000,"TIGHT MARGIN","HEALTHY")) | U6: Laba CEO/COO setelah promo tipis (< Rp1.000); rekomendasikan komisi Sales maksimal 10% untuk menjaga profitabilitas.
A7: =PRICING_ANALYSIS!A7 | B7: =PRICING_ANALYSIS!B7 | C7: =PRICING_ANALYSIS!C7 | D7: =PRICING_ANALYSIS!F7 | E7: =PRICING_ANALYSIS!E7 | F7: =D7-E7 | G7: 0.05 | H7: 5000 | I7: =MIN(D7*G7, H7) | J7: =D7-I7 | K7: =F7*0.10 | L7: =F7*0.15 | M7: =I7*0.5 | N7: =I7*0.5 | O7: =((F7-K7)/2)-M7 | P7: =((F7-L7)/2)-M7 | Q7: =((F7-K7)/2)-N7 | R7: =((F7-L7)/2)-N7 | S7: =F7-I7 | T7: =IF(P7<=0,"DEFICIT RISK",IF(P7<1000,"TIGHT MARGIN","HEALTHY")) | U7: Margin tebal; aman untuk promo 5% maksimal Rp5.000 dan komisi sales 10%-15%.
A8: =PRICING_ANALYSIS!A8 | B8: =PRICING_ANALYSIS!B8 | C8: =PRICING_ANALYSIS!C8 | D8: =PRICING_ANALYSIS!F8 | E8: =PRICING_ANALYSIS!E8 | F8: =D8-E8 | G8: 0.05 | H8: 5000 | I8: =MIN(D8*G8, H8) | J8: =D8-I8 | K8: =F8*0.10 | L8: =F8*0.15 | M8: =I8*0.5 | N8: =I8*0.5 | O8: =((F8-K8)/2)-M8 | P8: =((F8-L8)/2)-M8 | Q8: =((F8-K8)/2)-N8 | R8: =((F8-L8)/2)-N8 | S8: =F8-I8 | T8: =IF(P8<=0,"DEFICIT RISK",IF(P8<1000,"TIGHT MARGIN","HEALTHY")) | U8: Laba CEO/COO setelah promo tipis (< Rp1.000); rekomendasikan komisi Sales maksimal 10% untuk menjaga profitabilitas.
A9: =PRICING_ANALYSIS!A9 | B9: =PRICING_ANALYSIS!B9 | C9: =PRICING_ANALYSIS!C9 | D9: =PRICING_ANALYSIS!F9 | E9: =PRICING_ANALYSIS!E9 | F9: =D9-E9 | G9: 0.05 | H9: 5000 | I9: =MIN(D9*G9, H9) | J9: =D9-I9 | K9: =F9*0.10 | L9: =F9*0.15 | M9: =I9*0.5 | N9: =I9*0.5 | O9: =((F9-K9)/2)-M9 | P9: =((F9-L9)/2)-M9 | Q9: =((F9-K9)/2)-N9 | R9: =((F9-L9)/2)-N9 | S9: =F9-I9 | T9: =IF(P9<=0,"DEFICIT RISK",IF(P9<1000,"TIGHT MARGIN","HEALTHY")) | U9: Laba CEO/COO setelah promo tipis (< Rp1.000); rekomendasikan komisi Sales maksimal 10% untuk menjaga profitabilitas.
A10: =PRICING_ANALYSIS!A10 | B10: =PRICING_ANALYSIS!B10 | C10: =PRICING_ANALYSIS!C10 | D10: =PRICING_ANALYSIS!F10 | E10: =PRICING_ANALYSIS!E10 | F10: =D10-E10 | G10: 0.05 | H10: 5000 | I10: =MIN(D10*G10, H10) | J10: =D10-I10 | K10: =F10*0.10 | L10: =F10*0.15 | M10: =I10*0.5 | N10: =I10*0.5 | O10: =((F10-K10)/2)-M10 | P10: =((F10-L10)/2)-M10 | Q10: =((F10-K10)/2)-N10 | R10: =((F10-L10)/2)-N10 | S10: =F10-I10 | T10: =IF(P10<=0,"DEFICIT RISK",IF(P10<1000,"TIGHT MARGIN","HEALTHY")) | U10: Laba CEO/COO setelah promo tipis (< Rp1.000); rekomendasikan komisi Sales maksimal 10% untuk menjaga profitabilitas.
A11: =PRICING_ANALYSIS!A11 | B11: =PRICING_ANALYSIS!B11 | C11: =PRICING_ANALYSIS!C11 | D11: =PRICING_ANALYSIS!F11 | E11: =PRICING_ANALYSIS!E11 | F11: =D11-E11 | G11: 0.05 | H11: 5000 | I11: =MIN(D11*G11, H11) | J11: =D11-I11 | K11: =F11*0.10 | L11: =F11*0.15 | M11: =I11*0.5 | N11: =I11*0.5 | O11: =((F11-K11)/2)-M11 | P11: =((F11-L11)/2)-M11 | Q11: =((F11-K11)/2)-N11 | R11: =((F11-L11)/2)-N11 | S11: =F11-I11 | T11: =IF(P11<=0,"DEFICIT RISK",IF(P11<1000,"TIGHT MARGIN","HEALTHY")) | U11: Laba CEO/COO setelah promo tipis (< Rp1.000); rekomendasikan komisi Sales maksimal 10% untuk menjaga profitabilitas.
A12: =PRICING_ANALYSIS!A12 | B12: =PRICING_ANALYSIS!B12 | C12: =PRICING_ANALYSIS!C12 | D12: =PRICING_ANALYSIS!F12 | E12: =PRICING_ANALYSIS!E12 | F12: =D12-E12 | G12: 0.05 | H12: 5000 | I12: =MIN(D12*G12, H12) | J12: =D12-I12 | K12: =F12*0.10 | L12: =F12*0.15 | M12: =I12*0.5 | N12: =I12*0.5 | O12: =((F12-K12)/2)-M12 | P12: =((F12-L12)/2)-M12 | Q12: =((F12-K12)/2)-N12 | R12: =((F12-L12)/2)-N12 | S12: =F12-I12 | T12: =IF(P12<=0,"DEFICIT RISK",IF(P12<1000,"TIGHT MARGIN","HEALTHY")) | U12: Laba CEO/COO setelah promo tipis (< Rp1.000); rekomendasikan komisi Sales maksimal 10% untuk menjaga profitabilitas.
A13: =PRICING_ANALYSIS!A13 | B13: =PRICING_ANALYSIS!B13 | C13: =PRICING_ANALYSIS!C13 | D13: =PRICING_ANALYSIS!F13 | E13: =PRICING_ANALYSIS!E13 | F13: =D13-E13 | G13: 0.05 | H13: 5000 | I13: =MIN(D13*G13, H13) | J13: =D13-I13 | K13: =F13*0.10 | L13: =F13*0.15 | M13: =I13*0.5 | N13: =I13*0.5 | O13: =((F13-K13)/2)-M13 | P13: =((F13-L13)/2)-M13 | Q13: =((F13-K13)/2)-N13 | R13: =((F13-L13)/2)-N13 | S13: =F13-I13 | T13: =IF(P13<=0,"DEFICIT RISK",IF(P13<1000,"TIGHT MARGIN","HEALTHY")) | U13: Margin tebal; aman untuk promo 5% maksimal Rp5.000 dan komisi sales 10%-15%.
A14: =PRICING_ANALYSIS!A14 | B14: =PRICING_ANALYSIS!B14 | C14: =PRICING_ANALYSIS!C14 | D14: =PRICING_ANALYSIS!F14 | E14: =PRICING_ANALYSIS!E14 | F14: =D14-E14 | G14: 0.05 | H14: 5000 | I14: =MIN(D14*G14, H14) | J14: =D14-I14 | K14: =F14*0.10 | L14: =F14*0.15 | M14: =I14*0.5 | N14: =I14*0.5 | O14: =((F14-K14)/2)-M14 | P14: =((F14-L14)/2)-M14 | Q14: =((F14-K14)/2)-N14 | R14: =((F14-L14)/2)-N14 | S14: =F14-I14 | T14: =IF(P14<=0,"DEFICIT RISK",IF(P14<1000,"TIGHT MARGIN","HEALTHY")) | U14: Margin tebal; aman untuk promo 5% maksimal Rp5.000 dan komisi sales 10%-15%.
A15: =PRICING_ANALYSIS!A15 | B15: =PRICING_ANALYSIS!B15 | C15: =PRICING_ANALYSIS!C15 | D15: =PRICING_ANALYSIS!F15 | E15: =PRICING_ANALYSIS!E15 | F15: =D15-E15 | G15: 0.05 | H15: 5000 | I15: =MIN(D15*G15, H15) | J15: =D15-I15 | K15: =F15*0.10 | L15: =F15*0.15 | M15: =I15*0.5 | N15: =I15*0.5 | O15: =((F15-K15)/2)-M15 | P15: =((F15-L15)/2)-M15 | Q15: =((F15-K15)/2)-N15 | R15: =((F15-L15)/2)-N15 | S15: =F15-I15 | T15: =IF(P15<=0,"DEFICIT RISK",IF(P15<1000,"TIGHT MARGIN","HEALTHY")) | U15: Margin tebal; aman untuk promo 5% maksimal Rp5.000 dan komisi sales 10%-15%.
A16: =PRICING_ANALYSIS!A16 | B16: =PRICING_ANALYSIS!B16 | C16: =PRICING_ANALYSIS!C16 | D16: =PRICING_ANALYSIS!F16 | E16: =PRICING_ANALYSIS!E16 | F16: =D16-E16 | G16: 0.05 | H16: 5000 | I16: =MIN(D16*G16, H16) | J16: =D16-I16 | K16: =F16*0.10 | L16: =F16*0.15 | M16: =I16*0.5 | N16: =I16*0.5 | O16: =((F16-K16)/2)-M16 | P16: =((F16-L16)/2)-M16 | Q16: =((F16-K16)/2)-N16 | R16: =((F16-L16)/2)-N16 | S16: =F16-I16 | T16: =IF(P16<=0,"DEFICIT RISK",IF(P16<1000,"TIGHT MARGIN","HEALTHY")) | U16: Margin tebal; aman untuk promo 5% maksimal Rp5.000 dan komisi sales 10%-15%.
... A41: =PRICING_ANALYSIS!A41 | B41: =PRICING_ANALYSIS!B41 | C41: =PRICING_ANALYSIS!C41 | D41: =PRICING_ANALYSIS!F41 | E41: =PRICING_ANALYSIS!E41 | F41: =D41-E41 | G41: 0.05 | H41: 5000 | I41: =MIN(D41*G41, H41) | J41: =D41-I41 | K41: =F41*0.10 | L41: =F41*0.15 | M41: =I41*0.5 | N41: =I41*0.5 | O41: =((F41-K41)/2)-M41 | P41: =((F41-L41)/2)-M41 | Q41: =((F41-K41)/2)-N41 | R41: =((F41-L41)/2)-N41 | S41: =F41-I41 | T41: =IF(P41<=0,"DEFICIT RISK",IF(P41<1000,"TIGHT MARGIN","HEALTHY")) | U41: Margin tebal; aman untuk promo 5% maksimal Rp5.000 dan komisi sales 10%-15%.
A42: RATA-RATA | D42: =AVERAGE(D5:D41) | E42: =AVERAGE(E5:E41) | F42: =AVERAGE(F5:F41) | G42: =AVERAGE(G5:G41) | H42: =AVERAGE(H5:H41) | I42: =AVERAGE(I5:I41) | J42: =AVERAGE(J5:J41) | K42: =AVERAGE(K5:K41) | ... S42: =AVERAGE(S5:S41)

Sheet DATA_QUALITY
A1: ASTERRA STORE — AUDIT KUALITAS DATA & REKONSILIASI KATALOG AKTIF
A2: Pemeriksaan Kelengkapan, Validitas ID, Perbandingan Ekspektasi Produk Aktif vs Database Aktual
A4: 1. REKONSILIASI JUMLAH PRODUK AKTIF
A5: Parameter | B5: Nilai | C5: Status | D5: Keterangan
A6: Expected Active Products | B6: 37 | C6: BENCHMARK | D6: Target katalog aktif website Asterra Store
A7: Actual Active Products Found | B7: 37 | C7: MATCH | D7: Produk dengan Status Toko 'Aktif' di Database Master
A8: Reconciliation Variance (Difference) | B8: 0 | C8: PERFECT | D8: Selisih 0 produk — 100% konsisten antara referensi & database
A9: Total Database Catalog (Master DB) | B9: 232 | C9: FULL DB | D9: 37 Produk Aktif + 195 Produk Arsip (Nonaktif)
A10: Total Active Fallback JSON (active-catalog.json) | B10: 245 | C10: SNAPSHOT | D10: File snapshot cadangan saat database offline
A11: Produk Nonaktif / Arsip Yang Dikecualikan | B11: 195 | C11: EXCLUDED | D11: Produk arsip diabaikan dari analisis pricing sesuai instruksi
A14: 2. HASIL AUDIT KELENGKAPAN FIELD & INTEGRITAS DATA
A15: No | B15: Field Yang Diperiksa | C15: Jumlah Temuan Cacat / Kosong | D15: Toleransi | E15: Hasil Audit | F15: Catatan Kualitas
A16: 1 | B16: Missing Product ID | C16: 0 | D16: 0 | E16: PASS | F16: 100% ID terisi lengkap tanpa nilai null
A17: 2 | B17: Duplicate Product ID | C17: 0 | D17: 0 | E17: PASS | F17: Seluruh 37 ID bersifat unik (Primary Key)
A18: 3 | B18: Missing SKU / Code | C18: 0 | D18: 0 | E18: PASS | F18: Semua produk memiliki kode layanan provider
A19: 4 | B19: Duplicate SKU / Code | C19: 0 | D19: 0 | E19: PASS | F19: Semua kode layanan unik
A20: 5 | B20: Missing Product Name | C20: 0 | D20: 0 | E20: PASS | F20: Nama produk terisi lengkap dengan varian durasi & garansi
A21: 6 | B21: Missing Category | C21: 0 | D21: 0 | E21: PASS | F21: Semua produk terpetakan ke AI Tools / Apps & Streaming
A22: 7 | B22: Missing Cost Price | C22: 0 | D22: 0 | E22: PASS | F22: Harga modal pabrik tersedia valid untuk seluruh item
A23: 8 | B23: Missing Selling Price | C23: 0 | D23: 0 | E23: PASS | F23: Harga jual Asterra Store terisi valid
A24: 9 | B24: Invalid Price (Selling < Cost) | C24: 0 | D24: 0 | E24: PASS | F24: Tidak ada produk yang dijual rugi di bawah harga modal
A25: 10 | B25: Missing Availability Status | C25: 0 | D25: 0 | E25: PASS | F25: Status stok (Tersedia/Kosong) terdefinisi jelas
A26: 11 | B26: Missing Display Status | C26: 0 | D26: 0 | E26: PASS | F26: Status display toko seluruhnya bernilai 'Aktif'
